2788 - [INFO] [2017-02-18 18:49:12] - [C:\Python34\lib\site-packages\django\core\servers\basehttp.py:131] - "GET / HTTP/1.1" 200 6129
2788 - [INFO] [2017-02-18 18:49:12] - [C:\Python34\lib\site-packages\django\core\servers\basehttp.py:131] - "GET /static/css/bootstrap.min.css HTTP/1.1" 200 105317
2788 - [INFO] [2017-02-18 18:49:12] - [C:\Python34\lib\site-packages\django\core\servers\basehttp.py:131] - "GET /static/css/dashboard.css HTTP/1.1" 200 1619
2788 - [INFO] [2017-02-18 18:49:12] - [C:\Python34\lib\site-packages\django\core\servers\basehttp.py:131] - "GET /static/css/bootstrap_theme.min.css HTTP/1.1" 200 23416
2788 - [INFO] [2017-02-18 18:49:12] - [C:\Python34\lib\site-packages\django\core\servers\basehttp.py:131] - "GET /static/js/bootstrap.min.js HTTP/1.1" 200 37053
2788 - [INFO] [2017-02-18 18:49:12] - [C:\Python34\lib\site-packages\django\core\servers\basehttp.py:131] - "GET /static/css/main.css HTTP/1.1" 200 613
2788 - [INFO] [2017-02-18 18:49:12] - [C:\Python34\lib\site-packages\django\core\servers\basehttp.py:131] - "GET /static/css/3_3_7.bootstrap.min.css HTTP/1.1" 200 121207
2788 - [INFO] [2017-02-18 18:49:13] - [C:\Python34\lib\site-packages\django\core\servers\basehttp.py:131] - "GET /static/js/tether.min.js HTTP/1.1" 200 23310
2788 - [INFO] [2017-02-18 18:49:13] - [C:\Python34\lib\site-packages\django\core\servers\basehttp.py:131] - "GET /static/js/ie10-viewport-bug-workaround.js HTTP/1.1" 200 694
2788 - [INFO] [2017-02-18 18:49:13] - [C:\Python34\lib\site-packages\django\core\servers\basehttp.py:131] - "GET /static/js/jquery-3.1.1.min.js HTTP/1.1" 200 86713
2788 - [INFO] [2017-02-18 18:49:13] - [C:\Python34\lib\site-packages\django\core\servers\basehttp.py:131] - "GET /static/images/rango.jpg HTTP/1.1" 200 97522
2788 - [INFO] [2017-02-18 18:49:13] - [C:\Python34\lib\site-packages\django\core\servers\basehttp.py:131] - "GET /static/images/favicon.ico HTTP/1.1" 200 5430
2788 - [INFO] [2017-02-18 18:49:14] - [C:\Python34\lib\site-packages\django\core\servers\basehttp.py:131] - "GET /rango/category/python/ HTTP/1.1" 200 4061
2788 - [INFO] [2017-02-18 18:49:16] - [C:\Python34\lib\site-packages\django\core\servers\basehttp.py:131] - "GET /accounts/register/ HTTP/1.1" 200 4559
2788 - [INFO] [2017-02-18 18:49:17] - [C:\Python34\lib\site-packages\django\core\servers\basehttp.py:131] - "GET /accounts/login/ HTTP/1.1" 200 4330
2788 - [INFO] [2017-02-18 18:49:17] - [C:\Python34\lib\site-packages\django\core\servers\basehttp.py:131] - "GET /static/css/signin.css HTTP/1.1" 200 798
2788 - [INFO] [2017-02-18 18:49:18] - [C:\Python34\lib\site-packages\django\core\servers\basehttp.py:131] - "GET /rango/test/ HTTP/1.1" 200 12388
2788 - [INFO] [2017-02-18 18:49:18] - [C:\Python34\lib\site-packages\django\core\servers\basehttp.py:131] - "GET /media/cat.jpg.80x60_q85.jpg HTTP/1.1" 200 1251
2788 - [INFO] [2017-02-18 18:49:18] - [C:\Python34\lib\site-packages\django\core\servers\basehttp.py:131] - "GET /accounts/login/ HTTP/1.1" 200 4330
2788 - [INFO] [2017-02-18 18:49:19] - [C:\Python34\lib\site-packages\django\core\servers\basehttp.py:131] - "GET /accounts/register/ HTTP/1.1" 200 4559
2788 - [INFO] [2017-02-18 18:49:20] - [C:\Python34\lib\site-packages\django\core\servers\basehttp.py:131] - "GET /rango/ HTTP/1.1" 200 6129
10076 - [INFO] [2017-02-18 19:27:44] - [C:\Python34\lib\site-packages\django\core\servers\basehttp.py:131] - "GET /redis-demo HTTP/1.1" 301 0
10076 - [INFO] [2017-02-18 19:27:44] - [C:\Python34\lib\site-packages\django\core\servers\basehttp.py:131] - "GET /redis-demo/ HTTP/1.1" 200 147
10076 - [DEBUG] [2017-02-18 19:27:44] - [C:\Python34\lib\site-packages\django\template\base.py:929] - Exception while resolving variable 'name' in template 'unknown'.
Traceback (most recent call last):
  File "C:\Python34\lib\site-packages\django\core\handlers\exception.py", line 39, in inner
    response = get_response(request)
  File "C:\Python34\lib\site-packages\django\core\handlers\base.py", line 172, in _get_response
    resolver_match = resolver.resolve(request.path_info)
  File "C:\Python34\lib\site-packages\django\urls\resolvers.py", line 300, in resolve
    raise Resolver404({'tried': tried, 'path': new_path})
django.urls.exceptions.Resolver404: {'tried': [[<RegexURLPattern index ^$>], [<RegexURLResolver <module 'rango.urls' from 'C:\\Users\\Ê¤Åó\\Desktop\\tango_with_django\\rango\\urls.py'> (None:None) ^rango/>], [<RegexURLResolver <RegexURLPattern list> (admin:admin) ^admin/>], [<RegexURLResolver <module 'redis_demo.urls' from 'C:\\Users\\Ê¤Åó\\Desktop\\tango_with_django\\redis_demo\\urls.py'> (None:None) ^redis-demo/>], [<RegexURLPattern rigistration_register ^accounts/register>], [<RegexURLResolver <module 'registration.backends.simple.urls' from 'C:\\Python34\\lib\\site-packages\\registration\\backends\\simple\\urls.py'> (None:None) ^accounts/>], [<RegexURLPattern None ^media\/(?P<path>.*)$>], [<RegexURLPattern None ^static\/(?P<path>.*)$>]], 'path': 'favicon.ico'}

During handling of the above exception, another exception occurred:

Traceback (most recent call last):
  File "C:\Python34\lib\site-packages\django\template\base.py", line 885, in _resolve_lookup
    current = current[bit]
TypeError: 'RegexURLResolver' object is not subscriptable

During handling of the above exception, another exception occurred:

Traceback (most recent call last):
  File "C:\Python34\lib\site-packages\django\template\base.py", line 893, in _resolve_lookup
    current = getattr(current, bit)
AttributeError: 'RegexURLResolver' object has no attribute 'name'

During handling of the above exception, another exception occurred:

Traceback (most recent call last):
  File "C:\Python34\lib\site-packages\django\template\base.py", line 900, in _resolve_lookup
    current = current[int(bit)]
ValueError: invalid literal for int() with base 10: 'name'

During handling of the above exception, another exception occurred:

Traceback (most recent call last):
  File "C:\Python34\lib\site-packages\django\template\base.py", line 907, in _resolve_lookup
    (bit, current))  # missing attribute
django.template.base.VariableDoesNotExist: Failed lookup for key [name] in "<RegexURLResolver <module 'rango.urls' from 'C:\\\\Users\\\\Ê¤Åó\\\\Desktop\\\\tango_with_django\\\\rango\\\\urls.py'> (None:None) ^rango/>"
10076 - [DEBUG] [2017-02-18 19:27:44] - [C:\Python34\lib\site-packages\django\template\base.py:929] - Exception while resolving variable 'name' in template 'unknown'.
Traceback (most recent call last):
  File "C:\Python34\lib\site-packages\django\core\handlers\exception.py", line 39, in inner
    response = get_response(request)
  File "C:\Python34\lib\site-packages\django\core\handlers\base.py", line 172, in _get_response
    resolver_match = resolver.resolve(request.path_info)
  File "C:\Python34\lib\site-packages\django\urls\resolvers.py", line 300, in resolve
    raise Resolver404({'tried': tried, 'path': new_path})
django.urls.exceptions.Resolver404: {'tried': [[<RegexURLPattern index ^$>], [<RegexURLResolver <module 'rango.urls' from 'C:\\Users\\Ê¤Åó\\Desktop\\tango_with_django\\rango\\urls.py'> (None:None) ^rango/>], [<RegexURLResolver <RegexURLPattern list> (admin:admin) ^admin/>], [<RegexURLResolver <module 'redis_demo.urls' from 'C:\\Users\\Ê¤Åó\\Desktop\\tango_with_django\\redis_demo\\urls.py'> (None:None) ^redis-demo/>], [<RegexURLPattern rigistration_register ^accounts/register>], [<RegexURLResolver <module 'registration.backends.simple.urls' from 'C:\\Python34\\lib\\site-packages\\registration\\backends\\simple\\urls.py'> (None:None) ^accounts/>], [<RegexURLPattern None ^media\/(?P<path>.*)$>], [<RegexURLPattern None ^static\/(?P<path>.*)$>]], 'path': 'favicon.ico'}

During handling of the above exception, another exception occurred:

Traceback (most recent call last):
  File "C:\Python34\lib\site-packages\django\template\base.py", line 885, in _resolve_lookup
    current = current[bit]
TypeError: 'RegexURLResolver' object is not subscriptable

During handling of the above exception, another exception occurred:

Traceback (most recent call last):
  File "C:\Python34\lib\site-packages\django\template\base.py", line 893, in _resolve_lookup
    current = getattr(current, bit)
AttributeError: 'RegexURLResolver' object has no attribute 'name'

During handling of the above exception, another exception occurred:

Traceback (most recent call last):
  File "C:\Python34\lib\site-packages\django\template\base.py", line 900, in _resolve_lookup
    current = current[int(bit)]
ValueError: invalid literal for int() with base 10: 'name'

During handling of the above exception, another exception occurred:

Traceback (most recent call last):
  File "C:\Python34\lib\site-packages\django\template\base.py", line 907, in _resolve_lookup
    (bit, current))  # missing attribute
django.template.base.VariableDoesNotExist: Failed lookup for key [name] in '<RegexURLResolver <RegexURLPattern list> (admin:admin) ^admin/>'
10076 - [DEBUG] [2017-02-18 19:27:44] - [C:\Python34\lib\site-packages\django\template\base.py:929] - Exception while resolving variable 'name' in template 'unknown'.
Traceback (most recent call last):
  File "C:\Python34\lib\site-packages\django\core\handlers\exception.py", line 39, in inner
    response = get_response(request)
  File "C:\Python34\lib\site-packages\django\core\handlers\base.py", line 172, in _get_response
    resolver_match = resolver.resolve(request.path_info)
  File "C:\Python34\lib\site-packages\django\urls\resolvers.py", line 300, in resolve
    raise Resolver404({'tried': tried, 'path': new_path})
django.urls.exceptions.Resolver404: {'tried': [[<RegexURLPattern index ^$>], [<RegexURLResolver <module 'rango.urls' from 'C:\\Users\\Ê¤Åó\\Desktop\\tango_with_django\\rango\\urls.py'> (None:None) ^rango/>], [<RegexURLResolver <RegexURLPattern list> (admin:admin) ^admin/>], [<RegexURLResolver <module 'redis_demo.urls' from 'C:\\Users\\Ê¤Åó\\Desktop\\tango_with_django\\redis_demo\\urls.py'> (None:None) ^redis-demo/>], [<RegexURLPattern rigistration_register ^accounts/register>], [<RegexURLResolver <module 'registration.backends.simple.urls' from 'C:\\Python34\\lib\\site-packages\\registration\\backends\\simple\\urls.py'> (None:None) ^accounts/>], [<RegexURLPattern None ^media\/(?P<path>.*)$>], [<RegexURLPattern None ^static\/(?P<path>.*)$>]], 'path': 'favicon.ico'}

During handling of the above exception, another exception occurred:

Traceback (most recent call last):
  File "C:\Python34\lib\site-packages\django\template\base.py", line 885, in _resolve_lookup
    current = current[bit]
TypeError: 'RegexURLResolver' object is not subscriptable

During handling of the above exception, another exception occurred:

Traceback (most recent call last):
  File "C:\Python34\lib\site-packages\django\template\base.py", line 893, in _resolve_lookup
    current = getattr(current, bit)
AttributeError: 'RegexURLResolver' object has no attribute 'name'

During handling of the above exception, another exception occurred:

Traceback (most recent call last):
  File "C:\Python34\lib\site-packages\django\template\base.py", line 900, in _resolve_lookup
    current = current[int(bit)]
ValueError: invalid literal for int() with base 10: 'name'

During handling of the above exception, another exception occurred:

Traceback (most recent call last):
  File "C:\Python34\lib\site-packages\django\template\base.py", line 907, in _resolve_lookup
    (bit, current))  # missing attribute
django.template.base.VariableDoesNotExist: Failed lookup for key [name] in "<RegexURLResolver <module 'redis_demo.urls' from 'C:\\\\Users\\\\Ê¤Åó\\\\Desktop\\\\tango_with_django\\\\redis_demo\\\\urls.py'> (None:None) ^redis-demo/>"
10076 - [DEBUG] [2017-02-18 19:27:44] - [C:\Python34\lib\site-packages\django\template\base.py:929] - Exception while resolving variable 'name' in template 'unknown'.
Traceback (most recent call last):
  File "C:\Python34\lib\site-packages\django\core\handlers\exception.py", line 39, in inner
    response = get_response(request)
  File "C:\Python34\lib\site-packages\django\core\handlers\base.py", line 172, in _get_response
    resolver_match = resolver.resolve(request.path_info)
  File "C:\Python34\lib\site-packages\django\urls\resolvers.py", line 300, in resolve
    raise Resolver404({'tried': tried, 'path': new_path})
django.urls.exceptions.Resolver404: {'tried': [[<RegexURLPattern index ^$>], [<RegexURLResolver <module 'rango.urls' from 'C:\\Users\\Ê¤Åó\\Desktop\\tango_with_django\\rango\\urls.py'> (None:None) ^rango/>], [<RegexURLResolver <RegexURLPattern list> (admin:admin) ^admin/>], [<RegexURLResolver <module 'redis_demo.urls' from 'C:\\Users\\Ê¤Åó\\Desktop\\tango_with_django\\redis_demo\\urls.py'> (None:None) ^redis-demo/>], [<RegexURLPattern rigistration_register ^accounts/register>], [<RegexURLResolver <module 'registration.backends.simple.urls' from 'C:\\Python34\\lib\\site-packages\\registration\\backends\\simple\\urls.py'> (None:None) ^accounts/>], [<RegexURLPattern None ^media\/(?P<path>.*)$>], [<RegexURLPattern None ^static\/(?P<path>.*)$>]], 'path': 'favicon.ico'}

During handling of the above exception, another exception occurred:

Traceback (most recent call last):
  File "C:\Python34\lib\site-packages\django\template\base.py", line 885, in _resolve_lookup
    current = current[bit]
TypeError: 'RegexURLResolver' object is not subscriptable

During handling of the above exception, another exception occurred:

Traceback (most recent call last):
  File "C:\Python34\lib\site-packages\django\template\base.py", line 893, in _resolve_lookup
    current = getattr(current, bit)
AttributeError: 'RegexURLResolver' object has no attribute 'name'

During handling of the above exception, another exception occurred:

Traceback (most recent call last):
  File "C:\Python34\lib\site-packages\django\template\base.py", line 900, in _resolve_lookup
    current = current[int(bit)]
ValueError: invalid literal for int() with base 10: 'name'

During handling of the above exception, another exception occurred:

Traceback (most recent call last):
  File "C:\Python34\lib\site-packages\django\template\base.py", line 907, in _resolve_lookup
    (bit, current))  # missing attribute
django.template.base.VariableDoesNotExist: Failed lookup for key [name] in "<RegexURLResolver <module 'registration.backends.simple.urls' from 'C:\\\\Python34\\\\lib\\\\site-packages\\\\registration\\\\backends\\\\simple\\\\urls.py'> (None:None) ^accounts/>"
10076 - [WARNING] [2017-02-18 19:27:44] - [C:\Python34\lib\site-packages\django\core\handlers\base.py:152] - Not Found: /favicon.ico
10076 - [WARNING] [2017-02-18 19:27:44] - [C:\Python34\lib\site-packages\django\core\servers\basehttp.py:131] - "GET /favicon.ico HTTP/1.1" 404 2803
10076 - [INFO] [2017-02-18 22:33:44] - [C:\Python34\lib\site-packages\django\core\servers\basehttp.py:131] - "GET /redis-demo/ HTTP/1.1" 200 147
10076 - [INFO] [2017-02-18 22:33:45] - [C:\Python34\lib\site-packages\django\core\servers\basehttp.py:131] - "GET /redis-demo/ HTTP/1.1" 200 147
9788 - [INFO] [2017-02-18 22:46:06] - [C:\Python34\lib\site-packages\django\core\servers\basehttp.py:131] - "GET /redis-demo/ HTTP/1.1" 200 452
9788 - [INFO] [2017-02-18 22:46:47] - [C:\Python34\lib\site-packages\django\core\servers\basehttp.py:131] - "GET /redis-demo/ HTTP/1.1" 200 530
9788 - [INFO] [2017-02-18 22:47:03] - [C:\Python34\lib\site-packages\django\core\servers\basehttp.py:131] - "GET /redis-demo/ HTTP/1.1" 200 571
9788 - [INFO] [2017-02-18 22:47:04] - [C:\Python34\lib\site-packages\django\core\servers\basehttp.py:131] - "GET /redis-demo/ HTTP/1.1" 200 571
9788 - [INFO] [2017-02-18 22:47:23] - [C:\Python34\lib\site-packages\django\core\servers\basehttp.py:131] - "GET /redis-demo/ HTTP/1.1" 200 602
9788 - [INFO] [2017-02-18 22:47:28] - [C:\Python34\lib\site-packages\django\core\servers\basehttp.py:131] - "GET /redis-demo/ HTTP/1.1" 200 602
9788 - [INFO] [2017-02-18 22:47:45] - [C:\Python34\lib\site-packages\django\core\servers\basehttp.py:131] - "GET /redis-demo/ HTTP/1.1" 200 602
9788 - [INFO] [2017-02-18 22:50:01] - [C:\Python34\lib\site-packages\django\core\servers\basehttp.py:131] - "GET /redis-demo/ HTTP/1.1" 200 793
9788 - [INFO] [2017-02-18 22:50:35] - [C:\Python34\lib\site-packages\django\core\servers\basehttp.py:131] - "GET /redis-demo/ HTTP/1.1" 200 826
9788 - [INFO] [2017-02-18 22:50:44] - [C:\Python34\lib\site-packages\django\core\servers\basehttp.py:131] - "GET /redis-demo/ HTTP/1.1" 200 828
9788 - [INFO] [2017-02-18 22:51:23] - [C:\Python34\lib\site-packages\django\core\servers\basehttp.py:131] - "GET /redis-demo/ HTTP/1.1" 200 869
9788 - [INFO] [2017-02-18 22:52:02] - [C:\Python34\lib\site-packages\django\core\servers\basehttp.py:131] - "GET /redis-demo/ HTTP/1.1" 200 886
9788 - [INFO] [2017-02-18 22:52:03] - [C:\Python34\lib\site-packages\django\core\servers\basehttp.py:131] - "GET /redis-demo/ HTTP/1.1" 200 886
9788 - [INFO] [2017-02-18 22:52:15] - [C:\Python34\lib\site-packages\django\core\servers\basehttp.py:131] - "GET /redis-demo/ HTTP/1.1" 200 845
9788 - [INFO] [2017-02-18 22:52:16] - [C:\Python34\lib\site-packages\django\core\servers\basehttp.py:131] - "GET /redis-demo/ HTTP/1.1" 200 845
9788 - [INFO] [2017-02-18 22:52:16] - [C:\Python34\lib\site-packages\django\core\servers\basehttp.py:131] - "GET /redis-demo/ HTTP/1.1" 200 845
9788 - [INFO] [2017-02-18 22:53:03] - [C:\Python34\lib\site-packages\django\core\servers\basehttp.py:131] - "GET /redis-demo/ HTTP/1.1" 200 917
9788 - [INFO] [2017-02-18 22:53:04] - [C:\Python34\lib\site-packages\django\core\servers\basehttp.py:131] - "GET /redis-demo/ HTTP/1.1" 200 917
9788 - [INFO] [2017-02-18 22:53:19] - [C:\Python34\lib\site-packages\django\core\servers\basehttp.py:131] - "GET /redis-demo/ HTTP/1.1" 200 917
9788 - [INFO] [2017-02-18 22:53:19] - [C:\Python34\lib\site-packages\django\core\servers\basehttp.py:131] - "GET /redis-demo/ HTTP/1.1" 200 917
9788 - [INFO] [2017-02-18 22:53:19] - [C:\Python34\lib\site-packages\django\core\servers\basehttp.py:131] - "GET /redis-demo/ HTTP/1.1" 200 917
9788 - [INFO] [2017-02-18 22:53:20] - [C:\Python34\lib\site-packages\django\core\servers\basehttp.py:131] - "GET /redis-demo/ HTTP/1.1" 200 917
9788 - [INFO] [2017-02-18 22:53:21] - [C:\Python34\lib\site-packages\django\core\servers\basehttp.py:131] - "GET /redis-demo/ HTTP/1.1" 200 917
9788 - [INFO] [2017-02-18 22:54:29] - [C:\Python34\lib\site-packages\django\core\servers\basehttp.py:131] - "GET /redis-demo/ HTTP/1.1" 200 941
9788 - [INFO] [2017-02-18 22:54:31] - [C:\Python34\lib\site-packages\django\core\servers\basehttp.py:131] - "GET /redis-demo/ HTTP/1.1" 200 941
9788 - [INFO] [2017-02-18 22:54:31] - [C:\Python34\lib\site-packages\django\core\servers\basehttp.py:131] - "GET /redis-demo/ HTTP/1.1" 200 941
5856 - [INFO] [2017-02-18 22:59:46] - [C:\Python34\lib\site-packages\django\core\servers\basehttp.py:131] - "GET /redis-demo/ HTTP/1.1" 200 967
5856 - [WARNING] [2017-02-18 22:59:53] - [C:\Python34\lib\site-packages\django\middleware\csrf.py:158] - Forbidden (CSRF cookie not set.): /redis-demo/
5856 - [WARNING] [2017-02-18 22:59:53] - [C:\Python34\lib\site-packages\django\core\servers\basehttp.py:131] - "POST /redis-demo/ HTTP/1.1" 403 2857
5856 - [INFO] [2017-02-18 23:00:35] - [C:\Python34\lib\site-packages\django\core\servers\basehttp.py:131] - "GET / HTTP/1.1" 200 6129
5856 - [INFO] [2017-02-18 23:00:35] - [C:\Python34\lib\site-packages\django\core\servers\basehttp.py:131] - "GET /static/css/bootstrap.min.css HTTP/1.1" 200 105317
5856 - [INFO] [2017-02-18 23:00:35] - [C:\Python34\lib\site-packages\django\core\servers\basehttp.py:131] - "GET /static/css/bootstrap_theme.min.css HTTP/1.1" 200 23416
5856 - [INFO] [2017-02-18 23:00:35] - [C:\Python34\lib\site-packages\django\core\servers\basehttp.py:131] - "GET /static/css/main.css HTTP/1.1" 200 613
5856 - [INFO] [2017-02-18 23:00:35] - [C:\Python34\lib\site-packages\django\core\servers\basehttp.py:131] - "GET /static/css/dashboard.css HTTP/1.1" 200 1619
5856 - [INFO] [2017-02-18 23:00:35] - [C:\Python34\lib\site-packages\django\core\servers\basehttp.py:131] - "GET /static/css/3_3_7.bootstrap.min.css HTTP/1.1" 200 121207
5856 - [INFO] [2017-02-18 23:00:35] - [C:\Python34\lib\site-packages\django\core\servers\basehttp.py:131] - "GET /static/js/bootstrap.min.js HTTP/1.1" 200 37053
5856 - [INFO] [2017-02-18 23:00:35] - [C:\Python34\lib\site-packages\django\core\servers\basehttp.py:131] - "GET /static/js/jquery-3.1.1.min.js HTTP/1.1" 200 86713
5856 - [INFO] [2017-02-18 23:00:35] - [C:\Python34\lib\site-packages\django\core\servers\basehttp.py:131] - "GET /static/js/ie10-viewport-bug-workaround.js HTTP/1.1" 200 694
5856 - [INFO] [2017-02-18 23:00:35] - [C:\Python34\lib\site-packages\django\core\servers\basehttp.py:131] - "GET /static/js/tether.min.js HTTP/1.1" 200 23310
5856 - [INFO] [2017-02-18 23:00:35] - [C:\Python34\lib\site-packages\django\core\servers\basehttp.py:131] - "GET /static/images/rango.jpg HTTP/1.1" 200 97522
5856 - [INFO] [2017-02-18 23:00:36] - [C:\Python34\lib\site-packages\django\core\servers\basehttp.py:131] - "GET /rango/ HTTP/1.1" 200 6129
5856 - [DEBUG] [2017-02-18 23:00:37] - [C:\Python34\lib\site-packages\django\template\base.py:929] - Exception while resolving variable 'last_login' in template 'rango/about.html'.
Traceback (most recent call last):
  File "C:\Python34\lib\site-packages\django\template\base.py", line 885, in _resolve_lookup
    current = current[bit]
  File "C:\Python34\lib\site-packages\django\utils\functional.py", line 235, in inner
    return func(self._wrapped, *args)
TypeError: 'AnonymousUser' object is not subscriptable

During handling of the above exception, another exception occurred:

Traceback (most recent call last):
  File "C:\Python34\lib\site-packages\django\template\base.py", line 893, in _resolve_lookup
    current = getattr(current, bit)
  File "C:\Python34\lib\site-packages\django\utils\functional.py", line 235, in inner
    return func(self._wrapped, *args)
AttributeError: 'AnonymousUser' object has no attribute 'last_login'

During handling of the above exception, another exception occurred:

Traceback (most recent call last):
  File "C:\Python34\lib\site-packages\django\template\base.py", line 900, in _resolve_lookup
    current = current[int(bit)]
ValueError: invalid literal for int() with base 10: 'last_login'

During handling of the above exception, another exception occurred:

Traceback (most recent call last):
  File "C:\Python34\lib\site-packages\django\template\base.py", line 907, in _resolve_lookup
    (bit, current))  # missing attribute
django.template.base.VariableDoesNotExist: Failed lookup for key [last_login] in 'AnonymousUser'
5856 - [INFO] [2017-02-18 23:00:37] - [C:\Python34\lib\site-packages\django\core\servers\basehttp.py:131] - "GET /rango/about/ HTTP/1.1" 200 3852
5856 - [INFO] [2017-02-18 23:00:37] - [C:\Python34\lib\site-packages\django\core\servers\basehttp.py:131] - "GET /static/images/gua.png HTTP/1.1" 200 11844
5856 - [INFO] [2017-02-18 23:00:37] - [C:\Python34\lib\site-packages\django\core\servers\basehttp.py:131] - "GET /media/cat.jpg HTTP/1.1" 200 22744
5856 - [INFO] [2017-02-18 23:01:17] - [C:\Python34\lib\site-packages\django\core\servers\basehttp.py:131] - "GET /rango/test/ HTTP/1.1" 200 12388
5856 - [INFO] [2017-02-18 23:01:17] - [C:\Python34\lib\site-packages\django\core\servers\basehttp.py:131] - "GET /media/cat.jpg.80x60_q85.jpg HTTP/1.1" 200 1251
5856 - [INFO] [2017-02-18 23:03:53] - [C:\Python34\lib\site-packages\django\core\servers\basehttp.py:131] - "GET /redis-demo HTTP/1.1" 301 0
5856 - [INFO] [2017-02-18 23:03:53] - [C:\Python34\lib\site-packages\django\core\servers\basehttp.py:131] - "GET /redis-demo/ HTTP/1.1" 200 979
5856 - [WARNING] [2017-02-18 23:03:59] - [C:\Python34\lib\site-packages\django\middleware\csrf.py:158] - Forbidden (CSRF cookie not set.): /redis-demo/
5856 - [WARNING] [2017-02-18 23:03:59] - [C:\Python34\lib\site-packages\django\core\servers\basehttp.py:131] - "POST /redis-demo/ HTTP/1.1" 403 2857
5856 - [INFO] [2017-02-18 23:05:36] - [C:\Python34\lib\site-packages\django\core\servers\basehttp.py:131] - "GET /redis-demo/ HTTP/1.1" 200 1115
5856 - [ERROR] [2017-02-18 23:05:41] - [C:\Python34\lib\site-packages\django\core\handlers\exception.py:124] - Internal Server Error: /redis-demo/
Traceback (most recent call last):
  File "C:\Python34\lib\site-packages\django\core\handlers\exception.py", line 39, in inner
    response = get_response(request)
  File "C:\Python34\lib\site-packages\django\core\handlers\base.py", line 198, in _get_response
    "returned None instead." % (callback.__module__, view_name)
ValueError: The view redis_demo.views.index didn't return an HttpResponse object. It returned None instead.
5856 - [ERROR] [2017-02-18 23:05:41] - [C:\Python34\lib\site-packages\django\core\servers\basehttp.py:131] - "POST /redis-demo/ HTTP/1.1" 500 71206
5856 - [INFO] [2017-02-18 23:08:09] - [C:\Python34\lib\site-packages\django\core\servers\basehttp.py:131] - "GET /redis-demo/ HTTP/1.1" 200 1115
5856 - [ERROR] [2017-02-18 23:08:13] - [C:\Python34\lib\site-packages\django\core\handlers\exception.py:124] - Internal Server Error: /redis-demo/
Traceback (most recent call last):
  File "C:\Python34\lib\site-packages\django\core\handlers\exception.py", line 39, in inner
    response = get_response(request)
  File "C:\Python34\lib\site-packages\django\core\handlers\base.py", line 198, in _get_response
    "returned None instead." % (callback.__module__, view_name)
ValueError: The view redis_demo.views.index didn't return an HttpResponse object. It returned None instead.
5856 - [ERROR] [2017-02-18 23:08:13] - [C:\Python34\lib\site-packages\django\core\servers\basehttp.py:131] - "POST /redis-demo/ HTTP/1.1" 500 71206
4280 - [INFO] [2017-02-18 23:08:58] - [C:\Python34\lib\site-packages\django\core\servers\basehttp.py:131] - "POST /redis-demo/ HTTP/1.1" 302 0
4280 - [INFO] [2017-02-18 23:08:58] - [C:\Python34\lib\site-packages\django\core\servers\basehttp.py:131] - "GET /redis-demo/ HTTP/1.1" 200 1115
4280 - [INFO] [2017-02-18 23:09:05] - [C:\Python34\lib\site-packages\django\core\servers\basehttp.py:131] - "POST /redis-demo/ HTTP/1.1" 302 0
4280 - [INFO] [2017-02-18 23:09:05] - [C:\Python34\lib\site-packages\django\core\servers\basehttp.py:131] - "GET /redis-demo/ HTTP/1.1" 200 1112
4280 - [INFO] [2017-02-18 23:09:16] - [C:\Python34\lib\site-packages\django\core\servers\basehttp.py:131] - "POST /redis-demo/ HTTP/1.1" 302 0
4280 - [INFO] [2017-02-18 23:09:16] - [C:\Python34\lib\site-packages\django\core\servers\basehttp.py:131] - "GET /redis-demo/ HTTP/1.1" 200 1115
4280 - [INFO] [2017-02-18 23:10:55] - [C:\Python34\lib\site-packages\django\core\servers\basehttp.py:131] - "GET /redis-demo/ HTTP/1.1" 200 1115
4280 - [INFO] [2017-02-18 23:10:56] - [C:\Python34\lib\site-packages\django\core\servers\basehttp.py:131] - "GET /redis-demo/ HTTP/1.1" 200 1115
4280 - [INFO] [2017-02-18 23:10:59] - [C:\Python34\lib\site-packages\django\core\servers\basehttp.py:131] - "POST /redis-demo/ HTTP/1.1" 302 0
4280 - [INFO] [2017-02-18 23:10:59] - [C:\Python34\lib\site-packages\django\core\servers\basehttp.py:131] - "GET /redis-demo/ HTTP/1.1" 200 1108
4280 - [INFO] [2017-02-18 23:36:07] - [C:\Python34\lib\site-packages\django\core\servers\basehttp.py:131] - "GET /redis-demo/ HTTP/1.1" 200 1115
4280 - [INFO] [2017-02-18 23:36:12] - [C:\Python34\lib\site-packages\django\core\servers\basehttp.py:131] - "POST /redis-demo/ HTTP/1.1" 302 0
4280 - [INFO] [2017-02-18 23:36:12] - [C:\Python34\lib\site-packages\django\core\servers\basehttp.py:131] - "GET /redis-demo/ HTTP/1.1" 200 1112
4280 - [INFO] [2017-02-18 23:37:30] - [C:\Python34\lib\site-packages\django\core\servers\basehttp.py:131] - "POST /redis-demo/ HTTP/1.1" 302 0
4280 - [INFO] [2017-02-18 23:37:30] - [C:\Python34\lib\site-packages\django\core\servers\basehttp.py:131] - "GET /redis-demo/ HTTP/1.1" 200 1112
4280 - [ERROR] [2017-02-18 23:38:06] - [C:\Python34\lib\site-packages\django\core\handlers\exception.py:124] - Internal Server Error: /redis-demo/
Traceback (most recent call last):
  File "C:\Python34\lib\site-packages\django_redis\client\default.py", line 319, in decode
    value = int(value)
ValueError: invalid literal for int() with base 10: b'\xe5\xbe\x90\xe4\xb8\xbd\xe5\xa8\x85'

During handling of the above exception, another exception occurred:

Traceback (most recent call last):
  File "C:\Python34\lib\site-packages\django\core\handlers\exception.py", line 39, in inner
    response = get_response(request)
  File "C:\Python34\lib\site-packages\django\core\handlers\base.py", line 187, in _get_response
    response = self.process_exception_by_middleware(e, request)
  File "C:\Python34\lib\site-packages\django\core\handlers\base.py", line 185, in _get_response
    response = wrapped_callback(request, *callback_args, **callback_kwargs)
  File "C:\Users\Ê¤Åó\Desktop\tango_with_django\redis_demo\views.py", line 6, in index
    name = cache.get('name')
  File "C:\Python34\lib\site-packages\django_redis\cache.py", line 34, in _decorator
    return method(self, *args, **kwargs)
  File "C:\Python34\lib\site-packages\django_redis\cache.py", line 83, in get
    client=client)
  File "C:\Python34\lib\site-packages\django_redis\client\default.py", line 214, in get
    return self.decode(value)
  File "C:\Python34\lib\site-packages\django_redis\client\default.py", line 326, in decode
    value = self._serializer.loads(value)
  File "C:\Python34\lib\site-packages\django_redis\serializers\pickle.py", line 36, in loads
    return pickle.loads(force_bytes(value))
_pickle.UnpicklingError
4280 - [ERROR] [2017-02-18 23:38:06] - [C:\Python34\lib\site-packages\django\core\servers\basehttp.py:131] - "GET /redis-demo/ HTTP/1.1" 500 100971
4280 - [INFO] [2017-02-18 23:38:56] - [C:\Python34\lib\site-packages\django\core\servers\basehttp.py:131] - "GET /redis-demo/ HTTP/1.1" 200 1115
4280 - [INFO] [2017-02-18 23:38:58] - [C:\Python34\lib\site-packages\django\core\servers\basehttp.py:131] - "POST /redis-demo/ HTTP/1.1" 302 0
4280 - [INFO] [2017-02-18 23:38:58] - [C:\Python34\lib\site-packages\django\core\servers\basehttp.py:131] - "GET /redis-demo/ HTTP/1.1" 200 1109
4280 - [INFO] [2017-02-18 23:40:12] - [C:\Python34\lib\site-packages\django\core\servers\basehttp.py:131] - "POST /redis-demo/ HTTP/1.1" 302 0
4280 - [INFO] [2017-02-18 23:40:12] - [C:\Python34\lib\site-packages\django\core\servers\basehttp.py:131] - "GET /redis-demo/ HTTP/1.1" 200 1115
4280 - [INFO] [2017-02-18 23:40:12] - [C:\Python34\lib\site-packages\django\core\servers\basehttp.py:131] - "POST /redis-demo/ HTTP/1.1" 302 0
4280 - [INFO] [2017-02-18 23:40:12] - [C:\Python34\lib\site-packages\django\core\servers\basehttp.py:131] - "GET /redis-demo/ HTTP/1.1" 200 1115
4280 - [INFO] [2017-02-18 23:40:13] - [C:\Python34\lib\site-packages\django\core\servers\basehttp.py:131] - "POST /redis-demo/ HTTP/1.1" 302 0
4280 - [INFO] [2017-02-18 23:40:13] - [C:\Python34\lib\site-packages\django\core\servers\basehttp.py:131] - "GET /redis-demo/ HTTP/1.1" 200 1115
4280 - [INFO] [2017-02-18 23:40:13] - [C:\Python34\lib\site-packages\django\core\servers\basehttp.py:131] - "POST /redis-demo/ HTTP/1.1" 302 0
4280 - [INFO] [2017-02-18 23:40:13] - [C:\Python34\lib\site-packages\django\core\servers\basehttp.py:131] - "GET /redis-demo/ HTTP/1.1" 200 1115
4280 - [INFO] [2017-02-18 23:40:14] - [C:\Python34\lib\site-packages\django\core\servers\basehttp.py:131] - "POST /redis-demo/ HTTP/1.1" 302 0
4280 - [INFO] [2017-02-18 23:40:14] - [C:\Python34\lib\site-packages\django\core\servers\basehttp.py:131] - "GET /redis-demo/ HTTP/1.1" 200 1115
4280 - [INFO] [2017-02-18 23:40:15] - [C:\Python34\lib\site-packages\django\core\servers\basehttp.py:131] - "POST /redis-demo/ HTTP/1.1" 302 0
4280 - [INFO] [2017-02-18 23:40:15] - [C:\Python34\lib\site-packages\django\core\servers\basehttp.py:131] - "GET /redis-demo/ HTTP/1.1" 200 1115
4280 - [INFO] [2017-02-18 23:40:16] - [C:\Python34\lib\site-packages\django\core\servers\basehttp.py:131] - "POST /redis-demo/ HTTP/1.1" 302 0
4280 - [INFO] [2017-02-18 23:40:16] - [C:\Python34\lib\site-packages\django\core\servers\basehttp.py:131] - "GET /redis-demo/ HTTP/1.1" 200 1115
4280 - [INFO] [2017-02-18 23:40:21] - [C:\Python34\lib\site-packages\django\core\servers\basehttp.py:131] - "POST /redis-demo/ HTTP/1.1" 302 0
4280 - [INFO] [2017-02-18 23:40:21] - [C:\Python34\lib\site-packages\django\core\servers\basehttp.py:131] - "GET /redis-demo/ HTTP/1.1" 200 1118
4280 - [INFO] [2017-02-18 23:40:24] - [C:\Python34\lib\site-packages\django\core\servers\basehttp.py:131] - "POST /redis-demo/ HTTP/1.1" 302 0
4280 - [INFO] [2017-02-18 23:40:24] - [C:\Python34\lib\site-packages\django\core\servers\basehttp.py:131] - "GET /redis-demo/ HTTP/1.1" 200 1115
4280 - [INFO] [2017-02-18 23:40:25] - [C:\Python34\lib\site-packages\django\core\servers\basehttp.py:131] - "POST /redis-demo/ HTTP/1.1" 302 0
4280 - [INFO] [2017-02-18 23:40:25] - [C:\Python34\lib\site-packages\django\core\servers\basehttp.py:131] - "GET /redis-demo/ HTTP/1.1" 200 1115
4512 - [INFO] [2017-02-19 10:02:42] - [C:\Python34\lib\site-packages\django\core\servers\basehttp.py:131] - "GET /redis-demo/ HTTP/1.1" 200 1115
4512 - [DEBUG] [2017-02-19 10:02:42] - [C:\Python34\lib\site-packages\django\template\base.py:929] - Exception while resolving variable 'name' in template 'unknown'.
Traceback (most recent call last):
  File "C:\Python34\lib\site-packages\django\core\handlers\exception.py", line 39, in inner
    response = get_response(request)
  File "C:\Python34\lib\site-packages\django\core\handlers\base.py", line 172, in _get_response
    resolver_match = resolver.resolve(request.path_info)
  File "C:\Python34\lib\site-packages\django\urls\resolvers.py", line 300, in resolve
    raise Resolver404({'tried': tried, 'path': new_path})
django.urls.exceptions.Resolver404: {'path': 'favicon.ico', 'tried': [[<RegexURLPattern index ^$>], [<RegexURLResolver <module 'rango.urls' from 'C:\\Users\\Ê¤Åó\\Desktop\\tango_with_django\\rango\\urls.py'> (None:None) ^rango/>], [<RegexURLResolver <RegexURLPattern list> (admin:admin) ^admin/>], [<RegexURLResolver <module 'redis_demo.urls' from 'C:\\Users\\Ê¤Åó\\Desktop\\tango_with_django\\redis_demo\\urls.py'> (None:None) ^redis-demo/>], [<RegexURLPattern rigistration_register ^accounts/register>], [<RegexURLResolver <module 'registration.backends.simple.urls' from 'C:\\Python34\\lib\\site-packages\\registration\\backends\\simple\\urls.py'> (None:None) ^accounts/>], [<RegexURLPattern None ^media\/(?P<path>.*)$>], [<RegexURLPattern None ^static\/(?P<path>.*)$>]]}

During handling of the above exception, another exception occurred:

Traceback (most recent call last):
  File "C:\Python34\lib\site-packages\django\template\base.py", line 885, in _resolve_lookup
    current = current[bit]
TypeError: 'RegexURLResolver' object is not subscriptable

During handling of the above exception, another exception occurred:

Traceback (most recent call last):
  File "C:\Python34\lib\site-packages\django\template\base.py", line 893, in _resolve_lookup
    current = getattr(current, bit)
AttributeError: 'RegexURLResolver' object has no attribute 'name'

During handling of the above exception, another exception occurred:

Traceback (most recent call last):
  File "C:\Python34\lib\site-packages\django\template\base.py", line 900, in _resolve_lookup
    current = current[int(bit)]
ValueError: invalid literal for int() with base 10: 'name'

During handling of the above exception, another exception occurred:

Traceback (most recent call last):
  File "C:\Python34\lib\site-packages\django\template\base.py", line 907, in _resolve_lookup
    (bit, current))  # missing attribute
django.template.base.VariableDoesNotExist: Failed lookup for key [name] in "<RegexURLResolver <module 'rango.urls' from 'C:\\\\Users\\\\Ê¤Åó\\\\Desktop\\\\tango_with_django\\\\rango\\\\urls.py'> (None:None) ^rango/>"
4512 - [DEBUG] [2017-02-19 10:02:42] - [C:\Python34\lib\site-packages\django\template\base.py:929] - Exception while resolving variable 'name' in template 'unknown'.
Traceback (most recent call last):
  File "C:\Python34\lib\site-packages\django\core\handlers\exception.py", line 39, in inner
    response = get_response(request)
  File "C:\Python34\lib\site-packages\django\core\handlers\base.py", line 172, in _get_response
    resolver_match = resolver.resolve(request.path_info)
  File "C:\Python34\lib\site-packages\django\urls\resolvers.py", line 300, in resolve
    raise Resolver404({'tried': tried, 'path': new_path})
django.urls.exceptions.Resolver404: {'path': 'favicon.ico', 'tried': [[<RegexURLPattern index ^$>], [<RegexURLResolver <module 'rango.urls' from 'C:\\Users\\Ê¤Åó\\Desktop\\tango_with_django\\rango\\urls.py'> (None:None) ^rango/>], [<RegexURLResolver <RegexURLPattern list> (admin:admin) ^admin/>], [<RegexURLResolver <module 'redis_demo.urls' from 'C:\\Users\\Ê¤Åó\\Desktop\\tango_with_django\\redis_demo\\urls.py'> (None:None) ^redis-demo/>], [<RegexURLPattern rigistration_register ^accounts/register>], [<RegexURLResolver <module 'registration.backends.simple.urls' from 'C:\\Python34\\lib\\site-packages\\registration\\backends\\simple\\urls.py'> (None:None) ^accounts/>], [<RegexURLPattern None ^media\/(?P<path>.*)$>], [<RegexURLPattern None ^static\/(?P<path>.*)$>]]}

During handling of the above exception, another exception occurred:

Traceback (most recent call last):
  File "C:\Python34\lib\site-packages\django\template\base.py", line 885, in _resolve_lookup
    current = current[bit]
TypeError: 'RegexURLResolver' object is not subscriptable

During handling of the above exception, another exception occurred:

Traceback (most recent call last):
  File "C:\Python34\lib\site-packages\django\template\base.py", line 893, in _resolve_lookup
    current = getattr(current, bit)
AttributeError: 'RegexURLResolver' object has no attribute 'name'

During handling of the above exception, another exception occurred:

Traceback (most recent call last):
  File "C:\Python34\lib\site-packages\django\template\base.py", line 900, in _resolve_lookup
    current = current[int(bit)]
ValueError: invalid literal for int() with base 10: 'name'

During handling of the above exception, another exception occurred:

Traceback (most recent call last):
  File "C:\Python34\lib\site-packages\django\template\base.py", line 907, in _resolve_lookup
    (bit, current))  # missing attribute
django.template.base.VariableDoesNotExist: Failed lookup for key [name] in '<RegexURLResolver <RegexURLPattern list> (admin:admin) ^admin/>'
4512 - [DEBUG] [2017-02-19 10:02:42] - [C:\Python34\lib\site-packages\django\template\base.py:929] - Exception while resolving variable 'name' in template 'unknown'.
Traceback (most recent call last):
  File "C:\Python34\lib\site-packages\django\core\handlers\exception.py", line 39, in inner
    response = get_response(request)
  File "C:\Python34\lib\site-packages\django\core\handlers\base.py", line 172, in _get_response
    resolver_match = resolver.resolve(request.path_info)
  File "C:\Python34\lib\site-packages\django\urls\resolvers.py", line 300, in resolve
    raise Resolver404({'tried': tried, 'path': new_path})
django.urls.exceptions.Resolver404: {'path': 'favicon.ico', 'tried': [[<RegexURLPattern index ^$>], [<RegexURLResolver <module 'rango.urls' from 'C:\\Users\\Ê¤Åó\\Desktop\\tango_with_django\\rango\\urls.py'> (None:None) ^rango/>], [<RegexURLResolver <RegexURLPattern list> (admin:admin) ^admin/>], [<RegexURLResolver <module 'redis_demo.urls' from 'C:\\Users\\Ê¤Åó\\Desktop\\tango_with_django\\redis_demo\\urls.py'> (None:None) ^redis-demo/>], [<RegexURLPattern rigistration_register ^accounts/register>], [<RegexURLResolver <module 'registration.backends.simple.urls' from 'C:\\Python34\\lib\\site-packages\\registration\\backends\\simple\\urls.py'> (None:None) ^accounts/>], [<RegexURLPattern None ^media\/(?P<path>.*)$>], [<RegexURLPattern None ^static\/(?P<path>.*)$>]]}

During handling of the above exception, another exception occurred:

Traceback (most recent call last):
  File "C:\Python34\lib\site-packages\django\template\base.py", line 885, in _resolve_lookup
    current = current[bit]
TypeError: 'RegexURLResolver' object is not subscriptable

During handling of the above exception, another exception occurred:

Traceback (most recent call last):
  File "C:\Python34\lib\site-packages\django\template\base.py", line 893, in _resolve_lookup
    current = getattr(current, bit)
AttributeError: 'RegexURLResolver' object has no attribute 'name'

During handling of the above exception, another exception occurred:

Traceback (most recent call last):
  File "C:\Python34\lib\site-packages\django\template\base.py", line 900, in _resolve_lookup
    current = current[int(bit)]
ValueError: invalid literal for int() with base 10: 'name'

During handling of the above exception, another exception occurred:

Traceback (most recent call last):
  File "C:\Python34\lib\site-packages\django\template\base.py", line 907, in _resolve_lookup
    (bit, current))  # missing attribute
django.template.base.VariableDoesNotExist: Failed lookup for key [name] in "<RegexURLResolver <module 'redis_demo.urls' from 'C:\\\\Users\\\\Ê¤Åó\\\\Desktop\\\\tango_with_django\\\\redis_demo\\\\urls.py'> (None:None) ^redis-demo/>"
4512 - [DEBUG] [2017-02-19 10:02:42] - [C:\Python34\lib\site-packages\django\template\base.py:929] - Exception while resolving variable 'name' in template 'unknown'.
Traceback (most recent call last):
  File "C:\Python34\lib\site-packages\django\core\handlers\exception.py", line 39, in inner
    response = get_response(request)
  File "C:\Python34\lib\site-packages\django\core\handlers\base.py", line 172, in _get_response
    resolver_match = resolver.resolve(request.path_info)
  File "C:\Python34\lib\site-packages\django\urls\resolvers.py", line 300, in resolve
    raise Resolver404({'tried': tried, 'path': new_path})
django.urls.exceptions.Resolver404: {'path': 'favicon.ico', 'tried': [[<RegexURLPattern index ^$>], [<RegexURLResolver <module 'rango.urls' from 'C:\\Users\\Ê¤Åó\\Desktop\\tango_with_django\\rango\\urls.py'> (None:None) ^rango/>], [<RegexURLResolver <RegexURLPattern list> (admin:admin) ^admin/>], [<RegexURLResolver <module 'redis_demo.urls' from 'C:\\Users\\Ê¤Åó\\Desktop\\tango_with_django\\redis_demo\\urls.py'> (None:None) ^redis-demo/>], [<RegexURLPattern rigistration_register ^accounts/register>], [<RegexURLResolver <module 'registration.backends.simple.urls' from 'C:\\Python34\\lib\\site-packages\\registration\\backends\\simple\\urls.py'> (None:None) ^accounts/>], [<RegexURLPattern None ^media\/(?P<path>.*)$>], [<RegexURLPattern None ^static\/(?P<path>.*)$>]]}

During handling of the above exception, another exception occurred:

Traceback (most recent call last):
  File "C:\Python34\lib\site-packages\django\template\base.py", line 885, in _resolve_lookup
    current = current[bit]
TypeError: 'RegexURLResolver' object is not subscriptable

During handling of the above exception, another exception occurred:

Traceback (most recent call last):
  File "C:\Python34\lib\site-packages\django\template\base.py", line 893, in _resolve_lookup
    current = getattr(current, bit)
AttributeError: 'RegexURLResolver' object has no attribute 'name'

During handling of the above exception, another exception occurred:

Traceback (most recent call last):
  File "C:\Python34\lib\site-packages\django\template\base.py", line 900, in _resolve_lookup
    current = current[int(bit)]
ValueError: invalid literal for int() with base 10: 'name'

During handling of the above exception, another exception occurred:

Traceback (most recent call last):
  File "C:\Python34\lib\site-packages\django\template\base.py", line 907, in _resolve_lookup
    (bit, current))  # missing attribute
django.template.base.VariableDoesNotExist: Failed lookup for key [name] in "<RegexURLResolver <module 'registration.backends.simple.urls' from 'C:\\\\Python34\\\\lib\\\\site-packages\\\\registration\\\\backends\\\\simple\\\\urls.py'> (None:None) ^accounts/>"
4512 - [WARNING] [2017-02-19 10:02:42] - [C:\Python34\lib\site-packages\django\core\handlers\base.py:152] - Not Found: /favicon.ico
4512 - [WARNING] [2017-02-19 10:02:42] - [C:\Python34\lib\site-packages\django\core\servers\basehttp.py:131] - "GET /favicon.ico HTTP/1.1" 404 2803
4512 - [INFO] [2017-02-19 10:03:08] - [C:\Python34\lib\site-packages\django\core\servers\basehttp.py:131] - "POST /redis-demo/ HTTP/1.1" 302 0
4512 - [INFO] [2017-02-19 10:03:08] - [C:\Python34\lib\site-packages\django\core\servers\basehttp.py:131] - "GET /redis-demo/ HTTP/1.1" 200 1115
8364 - [ERROR] [2017-02-19 14:48:42] - [C:\Python34\lib\site-packages\django\core\handlers\exception.py:73] - Invalid HTTP_HOST header: '192.168.0.101:3000'. You may need to add '192.168.0.101' to ALLOWED_HOSTS.
8364 - [WARNING] [2017-02-19 14:48:42] - [C:\Python34\lib\site-packages\django\core\servers\basehttp.py:131] - "GET / HTTP/1.1" 400 75440
8364 - [ERROR] [2017-02-19 14:48:43] - [C:\Python34\lib\site-packages\django\core\handlers\exception.py:73] - Invalid HTTP_HOST header: '192.168.0.101:3000'. You may need to add '192.168.0.101' to ALLOWED_HOSTS.
8364 - [WARNING] [2017-02-19 14:48:43] - [C:\Python34\lib\site-packages\django\core\servers\basehttp.py:131] - "GET /favicon.ico HTTP/1.1" 400 75531
8364 - [ERROR] [2017-02-19 14:48:43] - [C:\Python34\lib\site-packages\django\core\handlers\exception.py:73] - Invalid HTTP_HOST header: '192.168.0.101:3000'. You may need to add '192.168.0.101' to ALLOWED_HOSTS.
8364 - [WARNING] [2017-02-19 14:48:43] - [C:\Python34\lib\site-packages\django\core\servers\basehttp.py:131] - "GET /favicon.ico HTTP/1.1" 400 75561
3816 - [INFO] [2017-02-19 14:51:25] - [C:\Python34\lib\site-packages\django\core\servers\basehttp.py:131] - "GET / HTTP/1.1" 200 6129
3816 - [INFO] [2017-02-19 14:51:25] - [C:\Python34\lib\site-packages\django\core\servers\basehttp.py:131] - "GET /static/css/bootstrap.min.css HTTP/1.1" 200 105317
3816 - [INFO] [2017-02-19 14:51:25] - [C:\Python34\lib\site-packages\django\core\servers\basehttp.py:131] - "GET /static/css/main.css HTTP/1.1" 200 613
3816 - [INFO] [2017-02-19 14:51:25] - [C:\Python34\lib\site-packages\django\core\servers\basehttp.py:131] - "GET /static/css/bootstrap_theme.min.css HTTP/1.1" 200 23416
3816 - [INFO] [2017-02-19 14:51:25] - [C:\Python34\lib\site-packages\django\core\servers\basehttp.py:131] - "GET /static/css/dashboard.css HTTP/1.1" 200 1619
3816 - [INFO] [2017-02-19 14:51:25] - [C:\Python34\lib\site-packages\django\core\servers\basehttp.py:131] - "GET /static/js/bootstrap.min.js HTTP/1.1" 200 37053
3816 - [INFO] [2017-02-19 14:51:25] - [C:\Python34\lib\site-packages\django\core\servers\basehttp.py:131] - "GET /static/css/3_3_7.bootstrap.min.css HTTP/1.1" 200 121207
3816 - [INFO] [2017-02-19 14:51:25] - [C:\Python34\lib\site-packages\django\core\servers\basehttp.py:131] - "GET /static/js/ie10-viewport-bug-workaround.js HTTP/1.1" 200 694
3816 - [INFO] [2017-02-19 14:51:25] - [C:\Python34\lib\site-packages\django\core\servers\basehttp.py:131] - "GET /static/js/jquery-3.1.1.min.js HTTP/1.1" 200 86713
3816 - [INFO] [2017-02-19 14:51:25] - [C:\Python34\lib\site-packages\django\core\servers\basehttp.py:131] - "GET /static/images/rango.jpg HTTP/1.1" 200 97522
3816 - [INFO] [2017-02-19 14:51:25] - [C:\Python34\lib\site-packages\django\core\servers\basehttp.py:131] - "GET /static/js/tether.min.js HTTP/1.1" 200 23310
3816 - [INFO] [2017-02-19 14:51:25] - [C:\Python34\lib\site-packages\django\core\servers\basehttp.py:131] - "GET /static/images/favicon.ico HTTP/1.1" 200 5430
3816 - [INFO] [2017-02-19 14:51:28] - [C:\Python34\lib\site-packages\django\core\servers\basehttp.py:131] - "GET /rango/ HTTP/1.1" 200 6129
3816 - [DEBUG] [2017-02-19 14:51:29] - [C:\Python34\lib\site-packages\django\template\base.py:929] - Exception while resolving variable 'last_login' in template 'rango/about.html'.
Traceback (most recent call last):
  File "C:\Python34\lib\site-packages\django\template\base.py", line 885, in _resolve_lookup
    current = current[bit]
  File "C:\Python34\lib\site-packages\django\utils\functional.py", line 235, in inner
    return func(self._wrapped, *args)
TypeError: 'AnonymousUser' object is not subscriptable

During handling of the above exception, another exception occurred:

Traceback (most recent call last):
  File "C:\Python34\lib\site-packages\django\template\base.py", line 893, in _resolve_lookup
    current = getattr(current, bit)
  File "C:\Python34\lib\site-packages\django\utils\functional.py", line 235, in inner
    return func(self._wrapped, *args)
AttributeError: 'AnonymousUser' object has no attribute 'last_login'

During handling of the above exception, another exception occurred:

Traceback (most recent call last):
  File "C:\Python34\lib\site-packages\django\template\base.py", line 900, in _resolve_lookup
    current = current[int(bit)]
ValueError: invalid literal for int() with base 10: 'last_login'

During handling of the above exception, another exception occurred:

Traceback (most recent call last):
  File "C:\Python34\lib\site-packages\django\template\base.py", line 907, in _resolve_lookup
    (bit, current))  # missing attribute
django.template.base.VariableDoesNotExist: Failed lookup for key [last_login] in 'AnonymousUser'
3816 - [INFO] [2017-02-19 14:51:29] - [C:\Python34\lib\site-packages\django\core\servers\basehttp.py:131] - "GET /rango/about/ HTTP/1.1" 200 3852
3816 - [INFO] [2017-02-19 14:51:30] - [C:\Python34\lib\site-packages\django\core\servers\basehttp.py:131] - "GET /static/images/gua.png HTTP/1.1" 200 11844
3816 - [INFO] [2017-02-19 14:51:30] - [C:\Python34\lib\site-packages\django\core\servers\basehttp.py:131] - "GET /media/cat.jpg HTTP/1.1" 200 22744
3816 - [INFO] [2017-02-19 14:51:30] - [C:\Python34\lib\site-packages\django\core\servers\basehttp.py:131] - "GET /accounts/register/ HTTP/1.1" 200 4559
3816 - [INFO] [2017-02-19 14:51:31] - [C:\Python34\lib\site-packages\django\core\servers\basehttp.py:131] - "GET /accounts/login/ HTTP/1.1" 200 4330
3816 - [INFO] [2017-02-19 14:51:32] - [C:\Python34\lib\site-packages\django\core\servers\basehttp.py:131] - "GET /static/css/signin.css HTTP/1.1" 200 798
3816 - [INFO] [2017-02-19 14:51:36] - [C:\Python34\lib\site-packages\django\core\servers\basehttp.py:131] - "GET /accounts/login/ HTTP/1.1" 200 4330
3816 - [INFO] [2017-02-19 14:51:37] - [C:\Python34\lib\site-packages\django\core\servers\basehttp.py:131] - "GET /accounts/register/ HTTP/1.1" 200 4559
3816 - [DEBUG] [2017-02-19 14:51:38] - [C:\Python34\lib\site-packages\django\template\base.py:929] - Exception while resolving variable 'last_login' in template 'rango/about.html'.
Traceback (most recent call last):
  File "C:\Python34\lib\site-packages\django\template\base.py", line 885, in _resolve_lookup
    current = current[bit]
  File "C:\Python34\lib\site-packages\django\utils\functional.py", line 235, in inner
    return func(self._wrapped, *args)
TypeError: 'AnonymousUser' object is not subscriptable

During handling of the above exception, another exception occurred:

Traceback (most recent call last):
  File "C:\Python34\lib\site-packages\django\template\base.py", line 893, in _resolve_lookup
    current = getattr(current, bit)
  File "C:\Python34\lib\site-packages\django\utils\functional.py", line 235, in inner
    return func(self._wrapped, *args)
AttributeError: 'AnonymousUser' object has no attribute 'last_login'

During handling of the above exception, another exception occurred:

Traceback (most recent call last):
  File "C:\Python34\lib\site-packages\django\template\base.py", line 900, in _resolve_lookup
    current = current[int(bit)]
ValueError: invalid literal for int() with base 10: 'last_login'

During handling of the above exception, another exception occurred:

Traceback (most recent call last):
  File "C:\Python34\lib\site-packages\django\template\base.py", line 907, in _resolve_lookup
    (bit, current))  # missing attribute
django.template.base.VariableDoesNotExist: Failed lookup for key [last_login] in 'AnonymousUser'
3816 - [INFO] [2017-02-19 14:51:38] - [C:\Python34\lib\site-packages\django\core\servers\basehttp.py:131] - "GET /rango/about/ HTTP/1.1" 200 3852
3816 - [DEBUG] [2017-02-19 14:51:48] - [C:\Python34\lib\site-packages\django\template\base.py:929] - Exception while resolving variable 'name' in template 'unknown'.
Traceback (most recent call last):
  File "C:\Python34\lib\site-packages\django\core\handlers\exception.py", line 39, in inner
    response = get_response(request)
  File "C:\Python34\lib\site-packages\django\core\handlers\base.py", line 172, in _get_response
    resolver_match = resolver.resolve(request.path_info)
  File "C:\Python34\lib\site-packages\django\urls\resolvers.py", line 300, in resolve
    raise Resolver404({'tried': tried, 'path': new_path})
django.urls.exceptions.Resolver404: {'tried': [[<RegexURLPattern index ^$>], [<RegexURLResolver <module 'rango.urls' from 'C:\\Users\\Ê¤Åó\\Desktop\\tango_with_django\\rango\\urls.py'> (None:None) ^rango/>], [<RegexURLResolver <RegexURLPattern list> (admin:admin) ^admin/>], [<RegexURLResolver <module 'redis_demo.urls' from 'C:\\Users\\Ê¤Åó\\Desktop\\tango_with_django\\redis_demo\\urls.py'> (None:None) ^redis-demo/>], [<RegexURLPattern rigistration_register ^accounts/register>], [<RegexURLResolver <module 'registration.backends.simple.urls' from 'C:\\Python34\\lib\\site-packages\\registration\\backends\\simple\\urls.py'> (None:None) ^accounts/>], [<RegexURLPattern None ^media\/(?P<path>.*)$>], [<RegexURLPattern None ^static\/(?P<path>.*)$>]], 'path': 'redis_demo'}

During handling of the above exception, another exception occurred:

Traceback (most recent call last):
  File "C:\Python34\lib\site-packages\django\template\base.py", line 885, in _resolve_lookup
    current = current[bit]
TypeError: 'RegexURLResolver' object is not subscriptable

During handling of the above exception, another exception occurred:

Traceback (most recent call last):
  File "C:\Python34\lib\site-packages\django\template\base.py", line 893, in _resolve_lookup
    current = getattr(current, bit)
AttributeError: 'RegexURLResolver' object has no attribute 'name'

During handling of the above exception, another exception occurred:

Traceback (most recent call last):
  File "C:\Python34\lib\site-packages\django\template\base.py", line 900, in _resolve_lookup
    current = current[int(bit)]
ValueError: invalid literal for int() with base 10: 'name'

During handling of the above exception, another exception occurred:

Traceback (most recent call last):
  File "C:\Python34\lib\site-packages\django\template\base.py", line 907, in _resolve_lookup
    (bit, current))  # missing attribute
django.template.base.VariableDoesNotExist: Failed lookup for key [name] in "<RegexURLResolver <module 'rango.urls' from 'C:\\\\Users\\\\Ê¤Åó\\\\Desktop\\\\tango_with_django\\\\rango\\\\urls.py'> (None:None) ^rango/>"
3816 - [DEBUG] [2017-02-19 14:51:48] - [C:\Python34\lib\site-packages\django\template\base.py:929] - Exception while resolving variable 'name' in template 'unknown'.
Traceback (most recent call last):
  File "C:\Python34\lib\site-packages\django\core\handlers\exception.py", line 39, in inner
    response = get_response(request)
  File "C:\Python34\lib\site-packages\django\core\handlers\base.py", line 172, in _get_response
    resolver_match = resolver.resolve(request.path_info)
  File "C:\Python34\lib\site-packages\django\urls\resolvers.py", line 300, in resolve
    raise Resolver404({'tried': tried, 'path': new_path})
django.urls.exceptions.Resolver404: {'tried': [[<RegexURLPattern index ^$>], [<RegexURLResolver <module 'rango.urls' from 'C:\\Users\\Ê¤Åó\\Desktop\\tango_with_django\\rango\\urls.py'> (None:None) ^rango/>], [<RegexURLResolver <RegexURLPattern list> (admin:admin) ^admin/>], [<RegexURLResolver <module 'redis_demo.urls' from 'C:\\Users\\Ê¤Åó\\Desktop\\tango_with_django\\redis_demo\\urls.py'> (None:None) ^redis-demo/>], [<RegexURLPattern rigistration_register ^accounts/register>], [<RegexURLResolver <module 'registration.backends.simple.urls' from 'C:\\Python34\\lib\\site-packages\\registration\\backends\\simple\\urls.py'> (None:None) ^accounts/>], [<RegexURLPattern None ^media\/(?P<path>.*)$>], [<RegexURLPattern None ^static\/(?P<path>.*)$>]], 'path': 'redis_demo'}

During handling of the above exception, another exception occurred:

Traceback (most recent call last):
  File "C:\Python34\lib\site-packages\django\template\base.py", line 885, in _resolve_lookup
    current = current[bit]
TypeError: 'RegexURLResolver' object is not subscriptable

During handling of the above exception, another exception occurred:

Traceback (most recent call last):
  File "C:\Python34\lib\site-packages\django\template\base.py", line 893, in _resolve_lookup
    current = getattr(current, bit)
AttributeError: 'RegexURLResolver' object has no attribute 'name'

During handling of the above exception, another exception occurred:

Traceback (most recent call last):
  File "C:\Python34\lib\site-packages\django\template\base.py", line 900, in _resolve_lookup
    current = current[int(bit)]
ValueError: invalid literal for int() with base 10: 'name'

During handling of the above exception, another exception occurred:

Traceback (most recent call last):
  File "C:\Python34\lib\site-packages\django\template\base.py", line 907, in _resolve_lookup
    (bit, current))  # missing attribute
django.template.base.VariableDoesNotExist: Failed lookup for key [name] in '<RegexURLResolver <RegexURLPattern list> (admin:admin) ^admin/>'
3816 - [DEBUG] [2017-02-19 14:51:48] - [C:\Python34\lib\site-packages\django\template\base.py:929] - Exception while resolving variable 'name' in template 'unknown'.
Traceback (most recent call last):
  File "C:\Python34\lib\site-packages\django\core\handlers\exception.py", line 39, in inner
    response = get_response(request)
  File "C:\Python34\lib\site-packages\django\core\handlers\base.py", line 172, in _get_response
    resolver_match = resolver.resolve(request.path_info)
  File "C:\Python34\lib\site-packages\django\urls\resolvers.py", line 300, in resolve
    raise Resolver404({'tried': tried, 'path': new_path})
django.urls.exceptions.Resolver404: {'tried': [[<RegexURLPattern index ^$>], [<RegexURLResolver <module 'rango.urls' from 'C:\\Users\\Ê¤Åó\\Desktop\\tango_with_django\\rango\\urls.py'> (None:None) ^rango/>], [<RegexURLResolver <RegexURLPattern list> (admin:admin) ^admin/>], [<RegexURLResolver <module 'redis_demo.urls' from 'C:\\Users\\Ê¤Åó\\Desktop\\tango_with_django\\redis_demo\\urls.py'> (None:None) ^redis-demo/>], [<RegexURLPattern rigistration_register ^accounts/register>], [<RegexURLResolver <module 'registration.backends.simple.urls' from 'C:\\Python34\\lib\\site-packages\\registration\\backends\\simple\\urls.py'> (None:None) ^accounts/>], [<RegexURLPattern None ^media\/(?P<path>.*)$>], [<RegexURLPattern None ^static\/(?P<path>.*)$>]], 'path': 'redis_demo'}

During handling of the above exception, another exception occurred:

Traceback (most recent call last):
  File "C:\Python34\lib\site-packages\django\template\base.py", line 885, in _resolve_lookup
    current = current[bit]
TypeError: 'RegexURLResolver' object is not subscriptable

During handling of the above exception, another exception occurred:

Traceback (most recent call last):
  File "C:\Python34\lib\site-packages\django\template\base.py", line 893, in _resolve_lookup
    current = getattr(current, bit)
AttributeError: 'RegexURLResolver' object has no attribute 'name'

During handling of the above exception, another exception occurred:

Traceback (most recent call last):
  File "C:\Python34\lib\site-packages\django\template\base.py", line 900, in _resolve_lookup
    current = current[int(bit)]
ValueError: invalid literal for int() with base 10: 'name'

During handling of the above exception, another exception occurred:

Traceback (most recent call last):
  File "C:\Python34\lib\site-packages\django\template\base.py", line 907, in _resolve_lookup
    (bit, current))  # missing attribute
django.template.base.VariableDoesNotExist: Failed lookup for key [name] in "<RegexURLResolver <module 'redis_demo.urls' from 'C:\\\\Users\\\\Ê¤Åó\\\\Desktop\\\\tango_with_django\\\\redis_demo\\\\urls.py'> (None:None) ^redis-demo/>"
3816 - [DEBUG] [2017-02-19 14:51:48] - [C:\Python34\lib\site-packages\django\template\base.py:929] - Exception while resolving variable 'name' in template 'unknown'.
Traceback (most recent call last):
  File "C:\Python34\lib\site-packages\django\core\handlers\exception.py", line 39, in inner
    response = get_response(request)
  File "C:\Python34\lib\site-packages\django\core\handlers\base.py", line 172, in _get_response
    resolver_match = resolver.resolve(request.path_info)
  File "C:\Python34\lib\site-packages\django\urls\resolvers.py", line 300, in resolve
    raise Resolver404({'tried': tried, 'path': new_path})
django.urls.exceptions.Resolver404: {'tried': [[<RegexURLPattern index ^$>], [<RegexURLResolver <module 'rango.urls' from 'C:\\Users\\Ê¤Åó\\Desktop\\tango_with_django\\rango\\urls.py'> (None:None) ^rango/>], [<RegexURLResolver <RegexURLPattern list> (admin:admin) ^admin/>], [<RegexURLResolver <module 'redis_demo.urls' from 'C:\\Users\\Ê¤Åó\\Desktop\\tango_with_django\\redis_demo\\urls.py'> (None:None) ^redis-demo/>], [<RegexURLPattern rigistration_register ^accounts/register>], [<RegexURLResolver <module 'registration.backends.simple.urls' from 'C:\\Python34\\lib\\site-packages\\registration\\backends\\simple\\urls.py'> (None:None) ^accounts/>], [<RegexURLPattern None ^media\/(?P<path>.*)$>], [<RegexURLPattern None ^static\/(?P<path>.*)$>]], 'path': 'redis_demo'}

During handling of the above exception, another exception occurred:

Traceback (most recent call last):
  File "C:\Python34\lib\site-packages\django\template\base.py", line 885, in _resolve_lookup
    current = current[bit]
TypeError: 'RegexURLResolver' object is not subscriptable

During handling of the above exception, another exception occurred:

Traceback (most recent call last):
  File "C:\Python34\lib\site-packages\django\template\base.py", line 893, in _resolve_lookup
    current = getattr(current, bit)
AttributeError: 'RegexURLResolver' object has no attribute 'name'

During handling of the above exception, another exception occurred:

Traceback (most recent call last):
  File "C:\Python34\lib\site-packages\django\template\base.py", line 900, in _resolve_lookup
    current = current[int(bit)]
ValueError: invalid literal for int() with base 10: 'name'

During handling of the above exception, another exception occurred:

Traceback (most recent call last):
  File "C:\Python34\lib\site-packages\django\template\base.py", line 907, in _resolve_lookup
    (bit, current))  # missing attribute
django.template.base.VariableDoesNotExist: Failed lookup for key [name] in "<RegexURLResolver <module 'registration.backends.simple.urls' from 'C:\\\\Python34\\\\lib\\\\site-packages\\\\registration\\\\backends\\\\simple\\\\urls.py'> (None:None) ^accounts/>"
3816 - [WARNING] [2017-02-19 14:51:48] - [C:\Python34\lib\site-packages\django\core\handlers\base.py:152] - Not Found: /redis_demo
3816 - [WARNING] [2017-02-19 14:51:48] - [C:\Python34\lib\site-packages\django\core\servers\basehttp.py:131] - "GET /redis_demo HTTP/1.1" 404 2804
3816 - [INFO] [2017-02-19 14:52:15] - [C:\Python34\lib\site-packages\django\core\servers\basehttp.py:131] - "GET /redis-demo HTTP/1.1" 301 0
3816 - [INFO] [2017-02-19 14:52:15] - [C:\Python34\lib\site-packages\django\core\servers\basehttp.py:131] - "GET /redis-demo/ HTTP/1.1" 200 1115
3816 - [INFO] [2017-02-19 14:52:25] - [C:\Python34\lib\site-packages\django\core\servers\basehttp.py:131] - "POST /redis-demo/ HTTP/1.1" 302 0
3816 - [INFO] [2017-02-19 14:52:25] - [C:\Python34\lib\site-packages\django\core\servers\basehttp.py:131] - "GET /redis-demo/ HTTP/1.1" 200 1111
3816 - [INFO] [2017-02-19 14:52:29] - [C:\Python34\lib\site-packages\django\core\servers\basehttp.py:131] - "POST /redis-demo/ HTTP/1.1" 302 0
3816 - [INFO] [2017-02-19 14:52:29] - [C:\Python34\lib\site-packages\django\core\servers\basehttp.py:131] - "GET /redis-demo/ HTTP/1.1" 200 1114
3816 - [INFO] [2017-02-19 14:52:31] - [C:\Python34\lib\site-packages\django\core\servers\basehttp.py:131] - "POST /redis-demo/ HTTP/1.1" 302 0
3816 - [INFO] [2017-02-19 14:52:31] - [C:\Python34\lib\site-packages\django\core\servers\basehttp.py:131] - "GET /redis-demo/ HTTP/1.1" 200 1110
3816 - [INFO] [2017-02-19 14:52:32] - [C:\Python34\lib\site-packages\django\core\servers\basehttp.py:131] - "GET /redis-demo/ HTTP/1.1" 200 1110
3816 - [INFO] [2017-02-19 14:52:33] - [C:\Python34\lib\site-packages\django\core\servers\basehttp.py:131] - "GET /redis-demo/ HTTP/1.1" 200 1110
3816 - [INFO] [2017-02-19 14:52:33] - [C:\Python34\lib\site-packages\django\core\servers\basehttp.py:131] - "GET /redis-demo/ HTTP/1.1" 200 1110
3816 - [INFO] [2017-02-19 14:52:33] - [C:\Python34\lib\site-packages\django\core\servers\basehttp.py:131] - "GET /redis-demo/ HTTP/1.1" 200 1110
3816 - [INFO] [2017-02-19 14:52:33] - [C:\Python34\lib\site-packages\django\core\servers\basehttp.py:131] - "GET /redis-demo/ HTTP/1.1" 200 1110
