10076 - [WARNING] [2017-02-18 19:27:44] - [C:\Python34\lib\site-packages\django\core\handlers\base.py:152] - Not Found: /favicon.ico
5856 - [WARNING] [2017-02-18 22:59:53] - [C:\Python34\lib\site-packages\django\middleware\csrf.py:158] - Forbidden (CSRF cookie not set.): /redis-demo/
5856 - [WARNING] [2017-02-18 23:03:59] - [C:\Python34\lib\site-packages\django\middleware\csrf.py:158] - Forbidden (CSRF cookie not set.): /redis-demo/
5856 - [ERROR] [2017-02-18 23:05:41] - [C:\Python34\lib\site-packages\django\core\handlers\exception.py:124] - Internal Server Error: /redis-demo/
Traceback (most recent call last):
  File "C:\Python34\lib\site-packages\django\core\handlers\exception.py", line 39, in inner
    response = get_response(request)
  File "C:\Python34\lib\site-packages\django\core\handlers\base.py", line 198, in _get_response
    "returned None instead." % (callback.__module__, view_name)
ValueError: The view redis_demo.views.index didn't return an HttpResponse object. It returned None instead.
5856 - [ERROR] [2017-02-18 23:08:13] - [C:\Python34\lib\site-packages\django\core\handlers\exception.py:124] - Internal Server Error: /redis-demo/
Traceback (most recent call last):
  File "C:\Python34\lib\site-packages\django\core\handlers\exception.py", line 39, in inner
    response = get_response(request)
  File "C:\Python34\lib\site-packages\django\core\handlers\base.py", line 198, in _get_response
    "returned None instead." % (callback.__module__, view_name)
ValueError: The view redis_demo.views.index didn't return an HttpResponse object. It returned None instead.
4280 - [ERROR] [2017-02-18 23:38:06] - [C:\Python34\lib\site-packages\django\core\handlers\exception.py:124] - Internal Server Error: /redis-demo/
Traceback (most recent call last):
  File "C:\Python34\lib\site-packages\django_redis\client\default.py", line 319, in decode
    value = int(value)
ValueError: invalid literal for int() with base 10: b'\xe5\xbe\x90\xe4\xb8\xbd\xe5\xa8\x85'

During handling of the above exception, another exception occurred:

Traceback (most recent call last):
  File "C:\Python34\lib\site-packages\django\core\handlers\exception.py", line 39, in inner
    response = get_response(request)
  File "C:\Python34\lib\site-packages\django\core\handlers\base.py", line 187, in _get_response
    response = self.process_exception_by_middleware(e, request)
  File "C:\Python34\lib\site-packages\django\core\handlers\base.py", line 185, in _get_response
    response = wrapped_callback(request, *callback_args, **callback_kwargs)
  File "C:\Users\ §≈Û\Desktop\tango_with_django\redis_demo\views.py", line 6, in index
    name = cache.get('name')
  File "C:\Python34\lib\site-packages\django_redis\cache.py", line 34, in _decorator
    return method(self, *args, **kwargs)
  File "C:\Python34\lib\site-packages\django_redis\cache.py", line 83, in get
    client=client)
  File "C:\Python34\lib\site-packages\django_redis\client\default.py", line 214, in get
    return self.decode(value)
  File "C:\Python34\lib\site-packages\django_redis\client\default.py", line 326, in decode
    value = self._serializer.loads(value)
  File "C:\Python34\lib\site-packages\django_redis\serializers\pickle.py", line 36, in loads
    return pickle.loads(force_bytes(value))
_pickle.UnpicklingError
4512 - [WARNING] [2017-02-19 10:02:42] - [C:\Python34\lib\site-packages\django\core\handlers\base.py:152] - Not Found: /favicon.ico
3816 - [WARNING] [2017-02-19 14:51:48] - [C:\Python34\lib\site-packages\django\core\handlers\base.py:152] - Not Found: /redis_demo
7024 - [ERROR] [2017-04-04 11:09:31] - [C:\Python34\lib\site-packages\django\core\handlers\exception.py:124] - Internal Server Error: /
Traceback (most recent call last):
  File "C:\Python34\lib\site-packages\django\core\handlers\exception.py", line 39, in inner
    response = get_response(request)
  File "C:\Python34\lib\site-packages\django\core\handlers\base.py", line 187, in _get_response
    response = self.process_exception_by_middleware(e, request)
  File "C:\Python34\lib\site-packages\django\core\handlers\base.py", line 185, in _get_response
    response = wrapped_callback(request, *callback_args, **callback_kwargs)
  File "C:\Users\linmu\Desktop\tango_with_django\rango\views.py", line 48, in index
    log(request.raw)
AttributeError: 'WSGIRequest' object has no attribute 'raw'
7024 - [WARNING] [2017-04-04 11:09:32] - [C:\Python34\lib\site-packages\django\core\handlers\base.py:152] - Not Found: /favicon.ico
7864 - [ERROR] [2017-04-04 11:17:01] - [C:\Python34\lib\site-packages\django\core\handlers\exception.py:124] - Internal Server Error: /rango/
Traceback (most recent call last):
  File "C:\Python34\lib\site-packages\django\core\handlers\exception.py", line 39, in inner
    response = get_response(request)
  File "C:\Python34\lib\site-packages\django\core\handlers\base.py", line 187, in _get_response
    response = self.process_exception_by_middleware(e, request)
  File "C:\Python34\lib\site-packages\django\core\handlers\base.py", line 185, in _get_response
    response = wrapped_callback(request, *callback_args, **callback_kwargs)
  File "C:\Users\linmu\Desktop\tango_with_django\rango\views.py", line 48, in index
    log(json.dumps(request.META))
  File "C:\Python34\lib\json\__init__.py", line 230, in dumps
    return _default_encoder.encode(obj)
  File "C:\Python34\lib\json\encoder.py", line 192, in encode
    chunks = self.iterencode(o, _one_shot=True)
  File "C:\Python34\lib\json\encoder.py", line 250, in iterencode
    return _iterencode(o, 0)
  File "C:\Python34\lib\json\encoder.py", line 173, in default
    raise TypeError(repr(o) + " is not JSON serializable")
TypeError: <class 'wsgiref.util.FileWrapper'> is not JSON serializable
